2013-07-24 18:58:24,194: DEBUG: root: 
========================================================
SETTING UP testrepo.tq_search.search_existing_ticket.test_fetch_existing_core_tickets.TestFetchExistingCoreTickets at 2013-07-24 18:58:24.194226
========================================================
2013-07-24 18:58:24,197: ERROR: ccengine.domain.configuration.AuthConfig: No option 'api_key' in section: 'auth'
2013-07-24 18:58:24,197: DEBUG: ccengine.common.connectors.rest: (<ccengine.clients.auth.auth_client.AuthClient object at 0x661d990>, 'POST', 'https://ws.integration.core.rackspace.com/ctkapi/login/melissa.biles') {'headers': {}, 'params': {}, 'data': '{"password": "qwerty"}', 'auth': None, 'verify': False}
2013-07-24 18:58:24,199: INFO: requests.packages.urllib3.connectionpool: Starting new HTTPS connection (1): ws.integration.core.rackspace.com
2013-07-24 18:58:24,421: DEBUG: requests.packages.urllib3.connectionpool: "POST /ctkapi/login/melissa.biles HTTP/1.1" 500 634
2013-07-24 18:58:24,422: DEBUG: ccengine.common.connectors.rest: 
------------
REQUEST SENT
------------
request method  : POST
request url     : https://ws.integration.core.rackspace.com/ctkapi/login/melissa.biles
request params  : 
request headers : CaseInsensitiveDict({'Content-Length': u'22', 'Accept-Encoding': 'gzip, deflate, compress', 'Accept': '*/*', 'User-Agent': 'python-requests/1.2.3 CPython/2.7.3 Linux/2.6.18-348.2.1.el5xen'})
request body    : {"password": "qwerty"}

2013-07-24 18:58:24,423: DEBUG: ccengine.common.connectors.rest: 
-----------------
RESPONSE RECIEVED
-----------------
response status  : <Response [500]>
response time    : 0.224624156952
response headers : CaseInsensitiveDict({'date': 'Wed, 24 Jul 2013 18:47:26 GMT', 'content-length': '634', 'content-type': 'text/html; charset=iso-8859-1', 'connection': 'close', 'server': 'Apache/2.2.3 (Red Hat)'})
response body    : <!DOCTYPE HTML PUBLIC "-//IETF//DTD HTML 2.0//EN">
<html><head>
<title>500 Internal Server Error</title>
</head><body>
<h1>Internal Server Error</h1>
<p>The server encountered an internal error or
misconfiguration and was unable to complete
your request.</p>
<p>Please contact the server administrator,
 root@localhost and inform them of the time the error occurred,
and anything you might have done that may have
caused the error.</p>
<p>More information about this error may be available
in the server error log.</p>
<hr>
<address>Apache/2.2.3 (Red Hat) Server at ws.integration.core.rackspace.com Port 443</address>
</body></html>

-------------------------------------------------------------------------------
2013-07-24 18:58:24,423: ERROR: ccengine.providers.auth.auth_api.AuthProvider: recieved a negative response from Core auth
2013-07-24 18:58:24,426: DEBUG: root: 
========================================================
SETTING UP testrepo.tq_search.search_existing_ticket.test_account_information.TestAccountInformation at 2013-07-24 18:58:24.426534
========================================================
2013-07-24 18:58:24,429: ERROR: ccengine.domain.configuration.AuthConfig: No option 'api_key' in section: 'auth'
2013-07-24 18:58:24,430: DEBUG: ccengine.common.connectors.rest: (<ccengine.clients.auth.auth_client.AuthClient object at 0x6623950>, 'POST', 'https://ws.integration.core.rackspace.com/ctkapi/login/melissa.biles') {'headers': {}, 'params': {}, 'data': '{"password": "qwerty"}', 'auth': None, 'verify': False}
2013-07-24 18:58:24,431: INFO: requests.packages.urllib3.connectionpool: Starting new HTTPS connection (1): ws.integration.core.rackspace.com
2013-07-24 18:58:24,653: DEBUG: requests.packages.urllib3.connectionpool: "POST /ctkapi/login/melissa.biles HTTP/1.1" 500 634
2013-07-24 18:58:24,655: DEBUG: ccengine.common.connectors.rest: 
------------
REQUEST SENT
------------
request method  : POST
request url     : https://ws.integration.core.rackspace.com/ctkapi/login/melissa.biles
request params  : 
request headers : CaseInsensitiveDict({'Content-Length': u'22', 'Accept-Encoding': 'gzip, deflate, compress', 'Accept': '*/*', 'User-Agent': 'python-requests/1.2.3 CPython/2.7.3 Linux/2.6.18-348.2.1.el5xen'})
request body    : {"password": "qwerty"}

2013-07-24 18:58:24,655: DEBUG: ccengine.common.connectors.rest: 
-----------------
RESPONSE RECIEVED
-----------------
response status  : <Response [500]>
response time    : 0.224449872971
response headers : CaseInsensitiveDict({'date': 'Wed, 24 Jul 2013 18:47:26 GMT', 'content-length': '634', 'content-type': 'text/html; charset=iso-8859-1', 'connection': 'close', 'server': 'Apache/2.2.3 (Red Hat)'})
response body    : <!DOCTYPE HTML PUBLIC "-//IETF//DTD HTML 2.0//EN">
<html><head>
<title>500 Internal Server Error</title>
</head><body>
<h1>Internal Server Error</h1>
<p>The server encountered an internal error or
misconfiguration and was unable to complete
your request.</p>
<p>Please contact the server administrator,
 root@localhost and inform them of the time the error occurred,
and anything you might have done that may have
caused the error.</p>
<p>More information about this error may be available
in the server error log.</p>
<hr>
<address>Apache/2.2.3 (Red Hat) Server at ws.integration.core.rackspace.com Port 443</address>
</body></html>

-------------------------------------------------------------------------------
2013-07-24 18:58:24,656: ERROR: ccengine.providers.auth.auth_api.AuthProvider: recieved a negative response from Core auth
2013-07-24 18:58:24,659: DEBUG: root: 
========================================================
SETTING UP testrepo.tq_search.search_existing_ticket.test_list_tickets.TestListTickets at 2013-07-24 18:58:24.659461
========================================================
2013-07-24 18:58:24,662: ERROR: ccengine.domain.configuration.AuthConfig: No option 'api_key' in section: 'auth'
2013-07-24 18:58:24,663: DEBUG: ccengine.common.connectors.rest: (<ccengine.clients.auth.auth_client.AuthClient object at 0x6629bd0>, 'POST', 'https://ws.integration.core.rackspace.com/ctkapi/login/melissa.biles') {'headers': {}, 'params': {}, 'data': '{"password": "qwerty"}', 'auth': None, 'verify': False}
2013-07-24 18:58:24,664: INFO: requests.packages.urllib3.connectionpool: Starting new HTTPS connection (1): ws.integration.core.rackspace.com
2013-07-24 18:58:24,912: DEBUG: requests.packages.urllib3.connectionpool: "POST /ctkapi/login/melissa.biles HTTP/1.1" 500 634
2013-07-24 18:58:24,914: DEBUG: ccengine.common.connectors.rest: 
------------
REQUEST SENT
------------
request method  : POST
request url     : https://ws.integration.core.rackspace.com/ctkapi/login/melissa.biles
request params  : 
request headers : CaseInsensitiveDict({'Content-Length': u'22', 'Accept-Encoding': 'gzip, deflate, compress', 'Accept': '*/*', 'User-Agent': 'python-requests/1.2.3 CPython/2.7.3 Linux/2.6.18-348.2.1.el5xen'})
request body    : {"password": "qwerty"}

2013-07-24 18:58:24,914: DEBUG: ccengine.common.connectors.rest: 
-----------------
RESPONSE RECIEVED
-----------------
response status  : <Response [500]>
response time    : 0.250432014465
response headers : CaseInsensitiveDict({'date': 'Wed, 24 Jul 2013 18:47:27 GMT', 'content-length': '634', 'content-type': 'text/html; charset=iso-8859-1', 'connection': 'close', 'server': 'Apache/2.2.3 (Red Hat)'})
response body    : <!DOCTYPE HTML PUBLIC "-//IETF//DTD HTML 2.0//EN">
<html><head>
<title>500 Internal Server Error</title>
</head><body>
<h1>Internal Server Error</h1>
<p>The server encountered an internal error or
misconfiguration and was unable to complete
your request.</p>
<p>Please contact the server administrator,
 root@localhost and inform them of the time the error occurred,
and anything you might have done that may have
caused the error.</p>
<p>More information about this error may be available
in the server error log.</p>
<hr>
<address>Apache/2.2.3 (Red Hat) Server at ws.integration.core.rackspace.com Port 443</address>
</body></html>

-------------------------------------------------------------------------------
2013-07-24 18:58:24,915: ERROR: ccengine.providers.auth.auth_api.AuthProvider: recieved a negative response from Core auth
2013-07-24 18:58:24,918: INFO: RunnerLog: 
=============================================
ERROR: setUpClass (testrepo.tq_search.test_health_check.TestHealthCheck)
---------------------------------------------
Traceback (most recent call last):
  File "/var/lib/jenkins/jobs/CloudCafeTest/workspace/lib/testrepo/common/testfixtures/tq_search.py", line 70, in setUpClass
    cls.core_provider = _CoreAPIProvider(config=core_config)
  File "/var/lib/jenkins/jobs/CloudCafeTest/workspace/lib/ccengine/providers/core/core_api.py", line 36, in __init__
    self.config.misc.deserializer)
  File "/var/lib/jenkins/jobs/CloudCafeTest/workspace/lib/ccengine/clients/core/core_api.py", line 17, in __init__
    self.auth_token = eval(auth_token).get("authtoken")
  File "<string>", line 1
    <!DOCTYPE HTML PUBLIC "-//IETF//DTD HTML 2.0//EN">
    ^
SyntaxError: invalid syntax

2013-07-24 18:58:24,918: INFO: RunnerLog: 
=============================================
ERROR: setUpClass (testrepo.tq_search.core_ongoing_sync.test_core_ongoing_sync.TestCoreOngoingSync)
---------------------------------------------
Traceback (most recent call last):
  File "/var/lib/jenkins/jobs/CloudCafeTest/workspace/lib/testrepo/tq_search/core_ongoing_sync/test_core_ongoing_sync.py", line 19, in setUpClass
    super(TestCoreOngoingSync, cls).setUpClass()
  File "/var/lib/jenkins/jobs/CloudCafeTest/workspace/lib/testrepo/common/testfixtures/tq_search.py", line 70, in setUpClass
    cls.core_provider = _CoreAPIProvider(config=core_config)
  File "/var/lib/jenkins/jobs/CloudCafeTest/workspace/lib/ccengine/providers/core/core_api.py", line 36, in __init__
    self.config.misc.deserializer)
  File "/var/lib/jenkins/jobs/CloudCafeTest/workspace/lib/ccengine/clients/core/core_api.py", line 17, in __init__
    self.auth_token = eval(auth_token).get("authtoken")
  File "<string>", line 1
    <!DOCTYPE HTML PUBLIC "-//IETF//DTD HTML 2.0//EN">
    ^
SyntaxError: invalid syntax

2013-07-24 18:58:24,919: INFO: RunnerLog: 
=============================================
ERROR: setUpClass (testrepo.tq_search.search_existing_ticket.test_pagination.TestPagination)
---------------------------------------------
Traceback (most recent call last):
  File "/var/lib/jenkins/jobs/CloudCafeTest/workspace/lib/testrepo/common/testfixtures/tq_search.py", line 70, in setUpClass
    cls.core_provider = _CoreAPIProvider(config=core_config)
  File "/var/lib/jenkins/jobs/CloudCafeTest/workspace/lib/ccengine/providers/core/core_api.py", line 36, in __init__
    self.config.misc.deserializer)
  File "/var/lib/jenkins/jobs/CloudCafeTest/workspace/lib/ccengine/clients/core/core_api.py", line 17, in __init__
    self.auth_token = eval(auth_token).get("authtoken")
  File "<string>", line 1
    <!DOCTYPE HTML PUBLIC "-//IETF//DTD HTML 2.0//EN">
    ^
SyntaxError: invalid syntax

2013-07-24 18:58:24,919: INFO: RunnerLog: 
=============================================
ERROR: setUpClass (testrepo.tq_search.search_existing_ticket.test_fetch_existing_core_tickets.TestFetchExistingCoreTickets)
---------------------------------------------
Traceback (most recent call last):
  File "/var/lib/jenkins/jobs/CloudCafeTest/workspace/lib/testrepo/common/testfixtures/tq_search.py", line 70, in setUpClass
    cls.core_provider = _CoreAPIProvider(config=core_config)
  File "/var/lib/jenkins/jobs/CloudCafeTest/workspace/lib/ccengine/providers/core/core_api.py", line 36, in __init__
    self.config.misc.deserializer)
  File "/var/lib/jenkins/jobs/CloudCafeTest/workspace/lib/ccengine/clients/core/core_api.py", line 17, in __init__
    self.auth_token = eval(auth_token).get("authtoken")
  File "<string>", line 1
    <!DOCTYPE HTML PUBLIC "-//IETF//DTD HTML 2.0//EN">
    ^
SyntaxError: invalid syntax

2013-07-24 18:58:24,920: INFO: RunnerLog: 
=============================================
ERROR: setUpClass (testrepo.tq_search.search_existing_ticket.test_account_information.TestAccountInformation)
---------------------------------------------
Traceback (most recent call last):
  File "/var/lib/jenkins/jobs/CloudCafeTest/workspace/lib/testrepo/tq_search/search_existing_ticket/test_account_information.py", line 24, in setUpClass
    super(TestAccountInformation, cls).setUpClass()
  File "/var/lib/jenkins/jobs/CloudCafeTest/workspace/lib/testrepo/common/testfixtures/tq_search.py", line 70, in setUpClass
    cls.core_provider = _CoreAPIProvider(config=core_config)
  File "/var/lib/jenkins/jobs/CloudCafeTest/workspace/lib/ccengine/providers/core/core_api.py", line 36, in __init__
    self.config.misc.deserializer)
  File "/var/lib/jenkins/jobs/CloudCafeTest/workspace/lib/ccengine/clients/core/core_api.py", line 17, in __init__
    self.auth_token = eval(auth_token).get("authtoken")
  File "<string>", line 1
    <!DOCTYPE HTML PUBLIC "-//IETF//DTD HTML 2.0//EN">
    ^
SyntaxError: invalid syntax

2013-07-24 18:58:24,920: INFO: RunnerLog: 
=============================================
ERROR: setUpClass (testrepo.tq_search.search_existing_ticket.test_list_tickets.TestListTickets)
---------------------------------------------
Traceback (most recent call last):
  File "/var/lib/jenkins/jobs/CloudCafeTest/workspace/lib/testrepo/common/testfixtures/tq_search.py", line 70, in setUpClass
    cls.core_provider = _CoreAPIProvider(config=core_config)
  File "/var/lib/jenkins/jobs/CloudCafeTest/workspace/lib/ccengine/providers/core/core_api.py", line 36, in __init__
    self.config.misc.deserializer)
  File "/var/lib/jenkins/jobs/CloudCafeTest/workspace/lib/ccengine/clients/core/core_api.py", line 17, in __init__
    self.auth_token = eval(auth_token).get("authtoken")
  File "<string>", line 1
    <!DOCTYPE HTML PUBLIC "-//IETF//DTD HTML 2.0//EN">
    ^
SyntaxError: invalid syntax

2013-07-24 18:58:24,921: INFO: RunnerLog: Ran 0 Tests
2013-07-24 18:58:24,921: INFO: RunnerLog: FAILED 
2013-07-24 18:58:24,922: INFO: RunnerLog:  (errors=6)

